Workbook

Sheet DataEntry
B1: Using a completed P-SSCRM questionnaire, or your own estimates,
B2: select the best answer from the dropdown in the answer column
A4: Company Id:
A5: Assessment Date:
A6: Team/Application:
A7: Assessor(s):
A8: Contributor(s):
C14: Answer | D14: Score
A15: Governance
B16: G.1 Perform compliance | E16: =AVERAGE(DataEntry!17:21)
B17: G.1.1 Organizational security requirements Do you have a defined secure SDLC that the engineers are aware of? How do you define security requirements and policies for the organization, its development infrastructure, contributions, and processes? How are these requirements and contributions maintained over time? How are constraints imposed by regulatory and compliance drivers included in these requirements, policies, and the SDLC? | D17: =IFERROR(VLOOKUP(C17,lookups!$A$1:$B$5,2,FALSE),0)
B18: G.1.2 Software license conflict How do you scan check that the software licenses for tools or third party components comply with your organization's use policies? Is the process automated? Do you document and track users and uses of software licenses relative to access control policies and software usage restrictions? | D18: =IFERROR(VLOOKUP(C18,lookups!$A$1:$B$5,2,FALSE),0)
B19: G.1.3 Produce attestation Can you tell me about automated or manual processes for producing artifacts that attest to the use of secure development practices? Where are the artifacts stored? What are your auditability/retention requirements for these artifacts? Is responsibility assigned for creating needed artifacts that tools cannot generate? Do you use a framework, like in-toto, to produce authenticated meta-data about artifacts, such as for attestation? Do you need to provide self-attestation for your product? Is the attestation immutable and published in the source repository releases, in the package registry, or elsewhere with their existence in a transparency log? | D19: =IFERROR(VLOOKUP(C19,lookups!$A$1:$B$5,2,FALSE),0)
B20: G.1.4 Deliver provenance Can you tell me more about your provenance data generation process? What authentications take place relative to the production of provenance data? Is provenance data automatically generated/verified by the build service, or does it involve a manual process or the ability for alteration, or is it read-only? Is a signing key used for a digital signature? Stored in a secure management system accessible only by the build service? Do provenance records include the initial state of the machine, VM, or container, and include all user-specified build steps? | D20: =IFERROR(VLOOKUP(C20,lookups!$A$1:$B$5,2,FALSE),0)
B21: G.1.5 Deliver SBOM Do you deliver an SBOM and provenance data that satisfy your contracts with software acquirers, such as in a standard-base format? How and when is the SBOM built? What tool do you use? Do you digitally sign the SBOMs? Do you produce a VEX supplement for your SBOM? What is your process for generating the VEX information? | D21: =IFERROR(VLOOKUP(C21,lookups!$A$1:$B$5,2,FALSE),0)
B22: G.2 Develop security policies | E22: =AVERAGE(DataEntry!23:28)
B23: G.2.1 Upper management support Can you share about upper management's commitment to secure software development? In what way is this commitment publicly demonstrated and communicated to development roles and responsibilities? Comment on the adequacy of resources dedicated to secure software development. | D23: =IFERROR(VLOOKUP(C23,lookups!$A$1:$B$5,2,FALSE),0)
B24: G.2.2 Secure SDLC checks What kind of criteria for security checks has been established, such as for security testing results? How can these checks indicate if security practices are being used and secure software is being developed? How are these checks tracked through the SDLC? Are the checks automated or manual? | D24: =IFERROR(VLOOKUP(C24,lookups!$A$1:$B$5,2,FALSE),0)
B25: G.2.3 Roles and responsibilities What security roles and responsibilities have been created to encompass all parts of the SDLC - both within the development teams as well as at an organizational level? | D25: =IFERROR(VLOOKUP(C25,lookups!$A$1:$B$5,2,FALSE),0)
B26: G.2.4 Security code review policy What kind of guidelines are set in place for which code should be manually or automatically reviewed from a security perspective? How are these guidelines communicated and enforced? | D26: =IFERROR(VLOOKUP(C26,lookups!$A$1:$B$5,2,FALSE),0)
B27: G.2.5 Asset inventory How is a system component inventory maintained for hardware, software licenses, software versions, component owners, machine names, and network addresses with identifiers for each of these? Is the components inventory process automated or manual? Are the artifacts machine-readable (such as through SBOM generation)? What process is used for the asset inventory to be updated when a product or system goes to end-of-life? | D27: =IFERROR(VLOOKUP(C27,lookups!$A$1:$B$5,2,FALSE),0)
B28: G.2.6 Protection of information at rest What provisions are made for the protection of information at rest included in agreements with suppliers, developers, system integrators, and external system providers? What policies are set in place for the use of cryptography in the organization’s security policy? | D28: =IFERROR(VLOOKUP(C28,lookups!$A$1:$B$5,2,FALSE),0)
B29: G.3 Manage suppliers | E29: =AVERAGE(DataEntry!30:34)
B30: G.3.1 Security-related contract terms What requirements language is included in system and services acquisition policies and contracts related to adherence to security policies, security requirements, and secure SDLC practices compatible with compliance requirements? Do you require SBOMs, provenance data, and attestation of adhering to security practices from your suppliers? How is adherence to contract terms verified? | D30: =IFERROR(VLOOKUP(C30,lookups!$A$1:$B$5,2,FALSE),0)
B31: G.3.2 Separation of duties How is separation of duties established for decisions that require the acquisition of information systems and supply chain components, such as components entering the enterprise's supply chain or contracted developers promoting code from development to production? | D31: =IFERROR(VLOOKUP(C31,lookups!$A$1:$B$5,2,FALSE),0)
B32: G.3.3 Information disclosure What kind of contract language is in place to stipulate that contractor systems conduct monitoring to detect unauthorized disclosure of any data? What kind of contract language is in place to require that vendors notify of unauthorized disclosure? | D32: =IFERROR(VLOOKUP(C32,lookups!$A$1:$B$5,2,FALSE),0)
B33: G.3.4 Session audits Under what circumstances are contract employees included in audits to identify security risks in the supply chain? | D33: =IFERROR(VLOOKUP(C33,lookups!$A$1:$B$5,2,FALSE),0)
B34: G.3.5 Notification agreement What notification agreements and monitoring capabilities are established with your suppliers related to supply chain threats or incidents? How much notification does a vendor provide when a product goes end-of-life? What end-of-life options exist? | D34: =IFERROR(VLOOKUP(C34,lookups!$A$1:$B$5,2,FALSE),0)
B35: G.4 Training | E35: =AVERAGE(DataEntry!36:38)
B36: G.4.1 Role-based training Can you tell me about the training given to employees and to vendors related to software supply chain security? Do you require team members to regularly participate in secure software architecture, design, development, testing, and software supply chain training and monitor their completion of training? Is the training specific to their roles, development tools, and language? | D36: =IFERROR(VLOOKUP(C36,lookups!$A$1:$B$5,2,FALSE),0)
B37: G.4.2 Contingency training Can you tell me about contingency training for preparing for emergency response, backup operations, and post-disaster recovery? | D37: =IFERROR(VLOOKUP(C37,lookups!$A$1:$B$5,2,FALSE),0)
B38: G.4.3 Gather attack trends How do you monitor new attack trends and vulnerabilities applicable to your software, such as by monitoring a cyberthreat intelligence feed and attacker forums, or attending conferences? | D38: =IFERROR(VLOOKUP(C38,lookups!$A$1:$B$5,2,FALSE),0)
B39: G.5 Assess and manage risk | E39: =AVERAGE(DataEntry!40:43)
B40: G.5.1 Criticality analysis What process do you have for performing criticality analysis as input to assessments of supply chain risk management activities? | D40: =IFERROR(VLOOKUP(C40,lookups!$A$1:$B$5,2,FALSE),0)
B41: G.5.2 Track security risks and decisions How are the responses to security risks and design decisions recorded, including how mitigations are to be achieved? How are approved exceptions to the security requirements periodically evaluated? | D41: =IFERROR(VLOOKUP(C41,lookups!$A$1:$B$5,2,FALSE),0)
B42: G.5.3 Security metrics What security metrics do you track to indicate how you are doing relative to developing secure software products and having an effective and efficient software security program (e.g., security outcomes, MTTR)? Are these metrics collected automatically or manually? | D42: =IFERROR(VLOOKUP(C42,lookups!$A$1:$B$5,2,FALSE),0)
B43: G.5.4 Data-informed product decisions Do you use the toolchain to gather information that informs security decision-making automatically? If not, is this information collected and reviewed manually? | D43: =IFERROR(VLOOKUP(C43,lookups!$A$1:$B$5,2,FALSE),0)
A44: Product
B45: P.1 Develop security requirements | E45: =AVERAGE(DataEntry!46:47)
B46: P.1.1 Product security requirements How are risk-reducing security architecture and design requirements for products considered and developed? Which of the following strategies are considered: the use of memory-safe languages, secure frameworks, isolation and sandboxing? Are completion and adherence tracked? | D46: =IFERROR(VLOOKUP(C46,lookups!$A$1:$B$5,2,FALSE),0)
...

Sheet lookups
A1: No | B1: 0
A2: Emerging | B2: 0.25
A3: Progress Being Made | B3: 0.5
A4: Almost There | B4: 0.75
A5: Funded | B5: 1

Sheet psscrm
A1: Practice | B1: Score
A2: G.1 Perform compliance | B2: =DataEntry!E16
A3: G.2 Develop security policies | B3: =DataEntry!E22
A4: G.3 Manage suppliers | B4: =DataEntry!E29
A5: G.4 Training | B5: =DataEntry!E35
A6: G.5 Assess and manage risk | B6: =DataEntry!E39
A7: P.1 Develop security requirements | B7: =DataEntry!E45
A8: P.2 Build security in | B8: =DataEntry!E48
A9: P.3 Manage component and container choices | B9: =DataEntry!E54
A10: P.4 Discover vulnerabilities | B10: =DataEntry!E60
A11: P.5 Manage vulnerable components and containers | B11: =DataEntry!E66
A12: E.1 Safeguard artifact integrity | B12: =DataEntry!E70
A13: E.2 Safeguard build integrity | B13: =DataEntry!E77
A14: E.3 Secure software development environment | B14: =DataEntry!E85
A15: D.1 Respond to/disclose vulnerabilities | B15: =DataEntry!E97
A16: D.2 Monitor intrusions/violations | B16: =DataEntry!E104
